<?xml version="1.0" encoding="utf-8"?>
<!-- This URDF was automatically created by SolidWorks to URDF Exporter! Originally created by Stephen Brawner (brawner@gmail.com) 
     Commit Version: 1.6.0-4-g7f85cfe  Build Version: 1.6.7995.38578
     For more information, please see http://wiki.ros.org/sw_urdf_exporter -->
<robot
  name="ROBOTIC_ARM_fullassembly_v3_simple.STEP">
  <link
    name="link_0">
    <inertial>
      <origin
        xyz="-0.071673 -0.26499 0.014756"
        rpy="0 0 0" />
      <mass
        value="0.4522" />
      <inertia
        ixx="0.0089012"
        ixy="1.472E-08"
        ixz="-1.456E-08"
        iyy="0.00011234"
        iyz="1.1401E-06"
        izz="0.0089658" />
    </inertial>
    <visual>
      <origin
        xyz="0 0 0"
        rpy="0 0 0" />
      <geometry>
        <mesh
          filename="package://ROBOTIC_ARM_fullassembly_v3_simple.STEP/meshes/link_0.STL" />
      </geometry>
      <material
        name="">
        <color
          rgba="0.79216 0.81961 0.93333 1" />
      </material>
    </visual>
    <collision>
      <origin
        xyz="0 0 0"
        rpy="0 0 0" />
      <geometry>
        <mesh
          filename="package://ROBOTIC_ARM_fullassembly_v3_simple.STEP/meshes/link_0.STL" />
      </geometry>
    </collision>
  </link>
  <link
    name="link_1">
    <inertial>
      <origin
        xyz="-2.2916E-13 -0.027055 -0.00111"
        rpy="0 0 0" />
      <mass
        value="0.33645" />
      <inertia
        ixx="0.00030458"
        ixy="9.6319E-17"
        ixz="7.2437E-17"
        iyy="0.00035766"
        iyz="1.0532E-05"
        izz="0.00042809" />
    </inertial>
    <visual>
      <origin
        xyz="0 0 0"
        rpy="0 0 0" />
      <geometry>
        <mesh
          filename="package://ROBOTIC_ARM_fullassembly_v3_simple.STEP/meshes/link_1.STL" />
      </geometry>
      <material
        name="">
        <color
          rgba="0.79216 0.81961 0.93333 1" />
      </material>
    </visual>
    <collision>
      <origin
        xyz="0 0 0"
        rpy="0 0 0" />
      <geometry>
        <mesh
          filename="package://ROBOTIC_ARM_fullassembly_v3_simple.STEP/meshes/link_1.STL" />
      </geometry>
    </collision>
  </link>
  <joint
    name="joint_1"
    type="prismatic">
    <origin
      xyz="-0.05405 -0.38652 0.04205"
      rpy="-1.5708 0 0" />
    <parent
      link="link_0" />
    <child
      link="link_1" />
    <axis
      xyz="0 0 1" />
    <limit
      lower="-0.275"
      upper="0.3"
      effort="0"
      velocity="0" />
  </joint>
  <link
    name="link_2">
    <inertial>
      <origin
        xyz="0.35774 -0.039768 0.0078455"
        rpy="0 0 0" />
      <mass
        value="0.34195" />
      <inertia
        ixx="0.00026464"
        ixy="-1.7686E-18"
        ixz="-2.5613E-19"
        iyy="0.0020281"
        iyz="-7.5E-06"
        izz="0.0021774" />
    </inertial>
    <visual>
      <origin
        xyz="0 0 0"
        rpy="0 0 0" />
      <geometry>
        <mesh
          filename="package://ROBOTIC_ARM_fullassembly_v3_simple.STEP/meshes/link_2.STL" />
      </geometry>
      <material
        name="">
        <color
          rgba="0.79216 0.81961 0.93333 1" />
      </material>
    </visual>
    <collision>
      <origin
        xyz="0 0 0"
        rpy="0 0 0" />
      <geometry>
        <mesh
          filename="package://ROBOTIC_ARM_fullassembly_v3_simple.STEP/meshes/link_2.STL" />
      </geometry>
    </collision>
  </link>
  <joint
    name="joint_2"
    type="revolute">
    <origin
      xyz="0 -0.0715 0.0585"
      rpy="-3.1416 0 -0.99807" />
    <parent
      link="link_1" />
    <child
      link="link_2" />
    <axis
      xyz="0 0 -1" />
    <limit
      lower="-1.047"
      upper="2.09"
      effort="0"
      velocity="0" />
  </joint>
  <link
    name="link_3">
    <inertial>
      <origin
        xyz="0.30148 4.5864E-05 0.0061642"
        rpy="0 0 0" />
      <mass
        value="0.23337" />
      <inertia
        ixx="0.00015718"
        ixy="-2.871E-07"
        ixz="-2.673E-13"
        iyy="0.0010986"
        iyz="1.3097E-12"
        izz="0.0011155" />
    </inertial>
    <visual>
      <origin
        xyz="0 0 0"
        rpy="0 0 0" />
      <geometry>
        <mesh
          filename="package://ROBOTIC_ARM_fullassembly_v3_simple.STEP/meshes/link_3.STL" />
      </geometry>
      <material
        name="">
        <color
          rgba="0.79216 0.81961 0.93333 1" />
      </material>
    </visual>
    <collision>
      <origin
        xyz="0 0 0"
        rpy="0 0 0" />
      <geometry>
        <mesh
          filename="package://ROBOTIC_ARM_fullassembly_v3_simple.STEP/meshes/link_3.STL" />
      </geometry>
    </collision>
  </link>
  <joint
    name="joint_3"
    type="revolute">
    <origin
      xyz="0.528 -0.093 -0.057"
      rpy="0 0 -1.6898" />
    <parent
      link="link_2" />
    <child
      link="link_3" />
    <axis
      xyz="0 0 -1" />
    <limit
      lower="-1.5"
      upper="4.6"
      effort="0"
      velocity="0" />
  </joint>
  <link
    name="link_4">
    <inertial>
      <origin
        xyz="0.017631 -4.774E-15 -3.3307E-16"
        rpy="0 0 0" />
      <mass
        value="0.048979" />
      <inertia
        ixx="2.6359E-05"
        ixy="8.4703E-22"
        ixz="-3.2585E-21"
        iyy="1.866E-05"
        iyz="1.0179E-07"
        izz="1.5094E-05" />
    </inertial>
    <visual>
      <origin
        xyz="0 0 0"
        rpy="0 0 0" />
      <geometry>
        <mesh
          filename="package://ROBOTIC_ARM_fullassembly_v3_simple.STEP/meshes/link_4.STL" />
      </geometry>
      <material
        name="">
        <color
          rgba="0.79216 0.81961 0.93333 1" />
      </material>
    </visual>
    <collision>
      <origin
        xyz="0 0 0"
        rpy="0 0 0" />
      <geometry>
        <mesh
          filename="package://ROBOTIC_ARM_fullassembly_v3_simple.STEP/meshes/link_4.STL" />
      </geometry>
    </collision>
  </link>
  <joint
    name="joint_4"
    type="revolute">
    <origin
      xyz="0.5095 0 0"
      rpy="0 0 0" />
    <parent
      link="link_3" />
    <child
      link="link_4" />
    <axis
      xyz="0 0 -1" />
    <limit
      lower="-1.57"
      upper="1.57"
      effort="0"
      velocity="0" />
  </joint>
  <link
    name="link_5">
    <inertial>
      <origin
        xyz="0 1.1102E-16 -5.5511E-17"
        rpy="0 0 0" />
      <mass
        value="0.018571" />
      <inertia
        ixx="5.9224E-06"
        ixy="3.1764E-22"
        ixz="9.9526E-21"
        iyy="5.9224E-06"
        iyz="4.2352E-21"
        izz="1.1767E-05" />
    </inertial>
    <visual>
      <origin
        xyz="0 0 0"
        rpy="0 0 0" />
      <geometry>
        <mesh
          filename="package://ROBOTIC_ARM_fullassembly_v3_simple.STEP/meshes/link_5.STL" />
      </geometry>
      <material
        name="">
        <color
          rgba="0.79216 0.81961 0.93333 1" />
      </material>
    </visual>
    <collision>
      <origin
        xyz="0 0 0"
        rpy="0 0 0" />
      <geometry>
        <mesh
          filename="package://ROBOTIC_ARM_fullassembly_v3_simple.STEP/meshes/link_5.STL" />
      </geometry>
    </collision>
  </link>
  <joint
    name="joint_5"
    type="continuous">
    <origin
      xyz="0.0445 0 0"
      rpy="1.5708 0.96794 1.5708" />
    <parent
      link="link_4" />
    <child
      link="link_5" />
    <axis
      xyz="0 0 1" />
  </joint>
</robot>